Workbook

Sheet Task 1 Data Validation & Cleani
B3: Missing Values of Fleet data | E3: Identifying Duplicates | H3: Total Anomaly Alerts
B4: =SUM(COUNTBLANK(Fleet_Data!E2:E811), COUNTBLANK(Fleet_Data!G2:G811), COUNTBLANK(Fleet_Data!J2:J811),COUNTBLANK(Fleet_Data!J2:J811)) -> 20 | E4: =COUNTIF(Fleet_Data!K2:K811, "Duplicate") -> 163 | H4: =COUNTIF(Fleet_Data!L2:L811, "Extreme Idle Outlier") + COUNTIF(Fleet_Data!M2:M811, "Suspiciously Low Efficiency") -> 69
B9: Reasoning
A10: 1 | B10: Vehicle_ID & Date: Audited to identify duplicates. A vehicle should only have one entry per day; duplicates artificially inflate total fleet distance and fuel metrics.
A11: 2 | B11: Fuel_Consumed_L, Idle_Time_Hrs, & Route_Compliance_Pct: Audited for missing values. These are the only columns containing blanks, which must be isolated so they don't skew fleet averages.
A12: 3 | B12: Distance_KM & Fuel_Consumed_L: Audited together to catch efficiency anomalies (e.g., extremely low KM/L), which immediately flag operational risks like fuel theft or leaks.
A13: 4 | B13: Idle_Time_Hrs: Audited to isolate extreme outliers (e.g., 12+ hours of idling), preventing sensor malfunctions or driver errors from distorting regular fleet benchmarks.
B15: Why Fuel Data Was Not Cleaned in Task 1:
A16: 1 | B16: 0 Missing Values: The dataset is 100% complete across all columns.
A17: 2 | B17: 0 Duplicates: Every timestamped event is verified as a unique record.
A18: 3 | B18: Anomalies are Intentional: Extreme values (odd hours) represent the actual operational risks (theft/leaks) .

Sheet Task 2 KPI_Analysis
A1: .
C2: Main Fleet KPIs
B4: Total Distance Travelled (KM) | E4: Total Fuel Consumed (L) | H4: Average Fuel Efficiency (KM/L) | L4: Average Idle Time (Hrs) | O4: Average Route Compliance (%)
B5: =SUM(Fleet_Data!D2:D811) -> 213815.7 | E5: =SUM(Fleet_Data!E2:E256) -> 16972.3 | H5: =SUM(Fleet_Data!D2:D811) / SUM(Fleet_Data!E2:E256) -> 12.597921 | L5: =AVERAGE(Fleet_Data!G2:G301) -> 2.3116667 | O5: =AVERAGE(Fleet_Data!J2:J488)/100 -> 0.92435934
B9: Top 5 Vehicle Leaderboards | E9: Top 5 Vehicles by Fuel Consumption
B11: Row Labels | C11: Sum of Distance_KM | E11: Row Labels | F11: Sum of Fuel_Consumed_L
B12: VH-003 | C12: 13622.6 | E12: VH-003 | F12: 3296.7
B13: VH-005 | C13: 12650.3 | E13: VH-005 | F13: 3237.2
B14: VH-011 | C14: 14013.8 | E14: VH-011 | F14: 3334.1
B15: VH-018 | C15: 15234.3 | E15: VH-018 | F15: 3687.6
B16: VH-020 | C16: 12803.5 | E16: VH-020 | F16: 3258.6
B17: Grand Total | C17: 68324.5 | E17: Grand Total | F17: 16814.2

Sheet Task 3 Business Insights
L1: VH ID | M1: Distance_KM | N1: Fuel_Consumed_L | O1: Fuel Efficient
L2: VH-009 | M2: 9519.5 | N2: 2498 | O2: =M2/N2 -> 3.8108487
L3: VH-001 | M3: 10172.9 | N3: 2661.6 | O3: =M3/N3 -> 3.8220995
A4: 1 | B4: Which vehicles are least fuel efficient? | L4: VH-005 | M4: 12650.3 | N4: 3237.2 | O4: =M4/N4 -> 3.9077907
A5: Ans | B5: By evaluating total distance against total fuel consumed per vehicle, VH-009 and VH-001 were identified as the least fuel-efficient assets in the fleet, both performing below 3.85 KM/L. | L5: VH-012 | M5: 9554.7 | N5: 2437.4 | O5: =M5/N5 -> 3.9200377
A7: 2 | B7: Which drivers have unusually high idle times? | M7: Column Labels
A8: Ans | B8: Against a fleet average of 2.36 hours, Driver R logs the highest unusual idle time at 2.66 hours per day, followed closely by Driver A (2.54 hrs), Driver L (2.53 hrs), Driver J (2.51 hrs), and Driver K (2.50 hrs). These five operators consistently exceed fleet benchmarks and should be targeted for fuel-saving behavior training. | M8: Driver R | N8: Driver L | O8: Driver K | P8: Driver J | Q8: Driver A | R8: Grand Total
L9: Average of Idle_Time_Hrs | M9: 2.6553571 | N9: 2.525641 | O9: 2.5 | P9: 2.5139535 | Q9: 2.5351351 | R9: 2.5511013
A11: 3 | B11: Which vehicles show abnormal fuel consumption?
A12: Ans | B12: VH-001 and VH-002
A13: - | B13: VH-001 has highly abnormal consumption ratios relative to its mileage, highlighted by a single day where it burned an extreme 120L for just 250KM (2.08 KM/L)
A14: - | B14: VH-002 shows an abnormal relationship between fuel drop alerts and engine idling patterns.
A16: 4 | B16: Which vehicles have poor route compliance? | M16: Column Labels
A17: Ans | B17: Against a fleet average baseline of 91.83%, the analysis reveals that VH-012 has the poorest route compliance at a low 89.98%, followed closely by VH-001 91.19%, VH-004 91.52%, VH-019 91.87%, and VH-003 92.11%. These five assets fall below the company operational baseline and require immediate route audit or driver coaching. | M17: VH-001 | N17: VH-002 | O17: VH-003 | P17: VH-004 | Q17: VH-006 | R17: VH-007 | S17: VH-008 | T17: VH-009 | U17: VH-010 | V17: VH-011 | W17: VH-012 | X17: VH-013 | Y17: VH-014 | Z17: VH-015 | AA17: VH-016 | AB17: VH-017 | AC17: VH-018 | AD17: VH-019 | AE17: VH-020 | AF17: (blank) | AG17: Grand Total
L18: Average of Route_Compliance_Pct | M18: 91.186486 | N18: 92.437143 | O18: 92.108333 | P18: 91.519512 | Q18: 92.5 | R18: 92.6875 | S18: 92.564286 | T18: 93.15 | U18: 93.282609 | V18: 93.328846 | W18: 89.984211 | X18: 92.897143 | Y18: 92.579412 | Z18: 93.039394 | AA18: 92.878049 | AB18: 92.182857 | AC18: 92.487273 | AD18: 91.871429 | AE18: 93.38125 | AG18: 92.452646
A19: 5 | B19: What operational improvements would you recommend?
A20: Ans 1 | B20: Driver Training Intervention: Mandate an immediate driving behavior review for Driver B regarding engine shut-off protocols to address the severe idling issues.
A21: Ans 2 | B21: Targeted Vehicle Maintenance / Auditing: Route VH-001 and VH-007 immediately to the maintenance depot. VH-001 needs a fuel tank/line check for leaks, and VH-007 requires a GPS tracking hardware inspection due to its chronically poor route compliance.
A22: Ans 3 | B22: Route Optimization: Review the dispatch paths for vehicles scoring below 91% route compliance to see if drivers are intentionally bypassing bad roads or heavy traffic zones, then update standard operating routes accordingly.

Sheet Fleet_Data
A1: Vehicle_ID | B1: Driver_Name | C1: Date | D1: Distance_KM | E1: Fuel_Consumed_L | F1: Fuel Efficient | G1: Idle_Time_Hrs | H1: Trips | I1: Average_Speed_KMH | J1: Route_Compliance_Pct | K1: Vehlicle Duplicate | L1: Spotting Suspicious Records | M1: Flagging Poor Fuel Efficiency
A2: VH-001 | B2: Driver A | C2: 46110 | D2: 346.7 | E2: 74.7 | F2: =IFERROR(D2/E2,0) -> 4.6412316 | G2: 2.5 | H2: 5 | I2: 64.6 | J2: 90.1 | K2: =IF(COUNTIFS($A$2:A2, A2, $C$2:C2, C2)>1, "Duplicate", "Unique") -> Unique | L2: =IF(G2 > (AVERAGE($G$2:$G$811) + (3 * _xlfn.STDEV.P($G$2:$G$811))), "Extreme Idle Outlier", "Normal") -> Normal | M2: =IFERROR(IF((D2 / E2) < 3, "Suspiciously Low Efficiency", "Normal"),0) -> Normal
A3: VH-001 | B3: Driver A | C3: 46036 | D3: 368 | E3: 108.5 | F3: =IFERROR(D3/E3,0) -> 3.3917051 | G3: 3.7 | H3: 8 | I3: 32.3 | J3: 88.7 | K3: =IF(COUNTIFS($A$2:A3, A3, $C$2:C3, C3)>1, "Duplicate", "Unique") -> Unique | L3: =IF(G3 > (AVERAGE($G$2:$G$811) + (3 * _xlfn.STDEV.P($G$2:$G$811))), "Extreme Idle Outlier", "Normal") -> Normal | M3: =IFERROR(IF((D3 / E3) < 3, "Suspiciously Low Efficiency", "Normal"),0) -> Normal
A4: VH-001 | B4: Driver A | C4: 46091 | D4: 126.8 | E4: 43.4 | F4: =IFERROR(D4/E4,0) -> 2.921659 | G4: 0.4 | H4: 5 | I4: 61.4 | J4: 86.9 | K4: =IF(COUNTIFS($A$2:A4, A4, $C$2:C4, C4)>1, "Duplicate", "Unique") -> Unique | L4: =IF(G4 > (AVERAGE($G$2:$G$811) + (3 * _xlfn.STDEV.P($G$2:$G$811))), "Extreme Idle Outlier", "Normal") -> Normal | M4: =IFERROR(IF((D4 / E4) < 3, "Suspiciously Low Efficiency", "Normal"),0) -> Suspiciously Low Efficiency
A5: VH-001 | B5: Driver A | C5: 46093 | D5: 231 | E5: 67.8 | F5: =IFERROR(D5/E5,0) -> 3.4070796 | G5: 3.8 | H5: 2 | I5: 50.8 | J5: 86.8 | K5: =IF(COUNTIFS($A$2:A5, A5, $C$2:C5, C5)>1, "Duplicate", "Unique") -> Unique | L5: =IF(G5 > (AVERAGE($G$2:$G$811) + (3 * _xlfn.STDEV.P($G$2:$G$811))), "Extreme Idle Outlier", "Normal") -> Normal | M5: =IFERROR(IF((D5 / E5) < 3, "Suspiciously Low Efficiency", "Normal"),0) -> Normal
A6: VH-001 | B6: Driver A | C6: 46068 | D6: 372.3 | E6: 108.2 | F6: =IFERROR(D6/E6,0) -> 3.4408503 | G6: 1.6 | H6: 3 | I6: 41.9 | J6: 86.9 | K6: =IF(COUNTIFS($A$2:A6, A6, $C$2:C6, C6)>1, "Duplicate", "Unique") -> Unique | L6: =IF(G6 > (AVERAGE($G$2:$G$811) + (3 * _xlfn.STDEV.P($G$2:$G$811))), "Extreme Idle Outlier", "Normal") -> Normal | M6: =IFERROR(IF((D6 / E6) < 3, "Suspiciously Low Efficiency", "Normal"),0) -> Normal
A7: VH-001 | B7: Driver A | C7: 46034 | D7: 356.1 | E7: 105.3 | F7: =IFERROR(D7/E7,0) -> 3.3817664 | G7: 2 | H7: 6 | I7: 37.1 | J7: 89.7 | K7: =IF(COUNTIFS($A$2:A7, A7, $C$2:C7, C7)>1, "Duplicate", "Unique") -> Unique | L7: =IF(G7 > (AVERAGE($G$2:$G$811) + (3 * _xlfn.STDEV.P($G$2:$G$811))), "Extreme Idle Outlier", "Normal") -> Normal | M7: =IFERROR(IF((D7 / E7) < 3, "Suspiciously Low Efficiency", "Normal"),0) -> Normal
A8: VH-001 | B8: Driver A | C8: 46076 | D8: 99.7 | E8: 24 | F8: =IFERROR(D8/E8,0) -> 4.1541667 | G8: 1.2 | H8: 2 | I8: 46.9 | J8: 85.4 | K8: =IF(COUNTIFS($A$2:A8, A8, $C$2:C8, C8)>1, "Duplicate", "Unique") -> Unique | L8: =IF(G8 > (AVERAGE($G$2:$G$811) + (3 * _xlfn.STDEV.P($G$2:$G$811))), "Extreme Idle Outlier", "Normal") -> Normal | M8: =IFERROR(IF((D8 / E8) < 3, "Suspiciously Low Efficiency", "Normal"),0) -> Normal
A9: VH-001 | B9: Driver A | C9: 46070 | D9: 202.6 | E9: 65.4 | F9: =IFERROR(D9/E9,0) -> 3.0978593 | G9: 2 | H9: 5 | I9: 65.9 | J9: 95.9 | K9: =IF(COUNTIFS($A$2:A9, A9, $C$2:C9, C9)>1, "Duplicate", "Unique") -> Unique | L9: =IF(G9 > (AVERAGE($G$2:$G$811) + (3 * _xlfn.STDEV.P($G$2:$G$811))), "Extreme Idle Outlier", "Normal") -> Normal | M9: =IFERROR(IF((D9 / E9) < 3, "Suspiciously Low Efficiency", "Normal"),0) -> Normal
A10: VH-001 | B10: Driver A | C10: 46099 | D10: 255.6 | E10: 47.2 | F10: =IFERROR(D10/E10,0) -> 5.4152542 | G10: 3.6 | H10: 4 | I10: 62.5 | J10: 93.8 | K10: =IF(COUNTIFS($A$2:A10, A10, $C$2:C10, C10)>1, "Duplicate", "Unique") -> Unique | L10: =IF(G10 > (AVERAGE($G$2:$G$811) + (3 * _xlfn.STDEV.P($G$2:$G$811))), "Extreme Idle Outlier", "Normal") -> Normal | M10: =IFERROR(IF((D10 / E10) < 3, "Suspiciously Low Efficiency", "Normal"),0) -> Normal
A11: VH-001 | B11: Driver A | C11: 46093 | D11: 441.8 | E11: 136.9 | F11: =IFERROR(D11/E11,0) -> 3.2271731 | G11: 3 | H11: 8 | I11: 51.5 | J11: 88 | K11: =IF(COUNTIFS($A$2:A11, A11, $C$2:C11, C11)>1, "Duplicate", "Unique") -> Duplicate | L11: =IF(G11 > (AVERAGE($G$2:$G$811) + (3 * _xlfn.STDEV.P($G$2:$G$811))), "Extreme Idle Outlier", "Normal") -> Normal | M11: =IFERROR(IF((D11 / E11) < 3, "Suspiciously Low Efficiency", "Normal"),0) -> Normal
A12: VH-001 | B12: Driver A | C12: 46066 | D12: 372.6 | E12: 86 | F12: =IFERROR(D12/E12,0) -> 4.3325581 | G12: 3.5 | H12: 3 | I12: 57.5 | J12: 94.6 | K12: =IF(COUNTIFS($A$2:A12, A12, $C$2:C12, C12)>1, "Duplicate", "Unique") -> Unique | L12: =IF(G12 > (AVERAGE($G$2:$G$811) + (3 * _xlfn.STDEV.P($G$2:$G$811))), "Extreme Idle Outlier", "Normal") -> Normal | M12: =IFERROR(IF((D12 / E12) < 3, "Suspiciously Low Efficiency", "Normal"),0) -> Normal
A13: VH-001 | B13: Driver A | C13: 46056 | D13: 321.9 | E13: 68.9 | F13: =IFERROR(D13/E13,0) -> 4.6719884 | G13: 0.5 | H13: 2 | I13: 50.9 | J13: 87.4 | K13: =IF(COUNTIFS($A$2:A13, A13, $C$2:C13, C13)>1, "Duplicate", "Unique") -> Unique | L13: =IF(G13 > (AVERAGE($G$2:$G$811) + (3 * _xlfn.STDEV.P($G$2:$G$811))), "Extreme Idle Outlier", "Normal") -> Normal | M13: =IFERROR(IF((D13 / E13) < 3, "Suspiciously Low Efficiency", "Normal"),0) -> Normal
... A256: VH-007 | B256: Driver G | C256: 46070 | D256: 431.5 | E256: 82.8 | F256: =IFERROR(D256/E256,0) -> 5.2113527 | G256: 3.5 | H256: 4 | I256: 30.8 | J256: 85.1 | K256: =IF(COUNTIFS($A$2:A256, A256, $C$2:C256, C256)>1, "Duplicate", "Unique") -> Unique | L256: =IF(G256 > (AVERAGE($G$2:$G$811) + (3 * _xlfn.STDEV.P($G$2:$G$811))), "Extreme Idle Outlier", "Normal") -> Normal | M256: =IFERROR(IF((D256 / E256) < 3, "Suspiciously Low Efficiency", "Normal"),0) -> Normal
A257: VH-007 | B257: Driver G | C257: 46107 | D257: 202.8 | F257: =IFERROR(D257/E257,0) -> 0 | G257: 1.1 | H257: 8 | I257: 74.8 | J257: 97.4 | K257: =IF(COUNTIFS($A$2:A257, A257, $C$2:C257, C257)>1, "Duplicate", "Unique") -> Unique | L257: =IF(G257 > (AVERAGE($G$2:$G$811) + (3 * _xlfn.STDEV.P($G$2:$G$811))), "Extreme Idle Outlier", "Normal") -> Normal | M257: =IFERROR(IF((D257 / E257) < 3, "Suspiciously Low Efficiency", "Normal"),0) -> 0
A258: VH-007 | B258: Driver G | C258: 46110 | D258: 237 | E258: 76.9 | F258: =IFERROR(D258/E258,0) -> 3.0819246 | G258: 2.5 | H258: 7 | I258: 59.1 | J258: 99.1 | K258: =IF(COUNTIFS($A$2:A258, A258, $C$2:C258, C258)>1, "Duplicate", "Unique") -> Unique | L258: =IF(G258 > (AVERAGE($G$2:$G$811) + (3 * _xlfn.STDEV.P($G$2:$G$811))), "Extreme Idle Outlier", "Normal") -> Normal | M258: =IFERROR(IF((D258 / E258) < 3, "Suspiciously Low Efficiency", "Normal"),0) -> Normal
A259: VH-007 | B259: Driver G | C259: 46098 | D259: 139.7 | E259: 27.7 | F259: =IFERROR(D259/E259,0) -> 5.0433213 | G259: 0.3 | H259: 1 | I259: 35.8 | J259: 93.9 | K259: =IF(COUNTIFS($A$2:A259, A259, $C$2:C259, C259)>1, "Duplicate", "Unique") -> Duplicate | L259: =IF(G259 > (AVERAGE($G$2:$G$811) + (3 * _xlfn.STDEV.P($G$2:$G$811))), "Extreme Idle Outlier", "Normal") -> Normal | M259: =IFERROR(IF((D259 / E259) < 3, "Suspiciously Low Efficiency", "Normal"),0) -> Normal
A260: VH-007 | B260: Driver G | C260: 46111 | D260: 377.6 | E260: 96.7 | F260: =IFERROR(D260/E260,0) -> 3.9048604 | G260: 0.7 | H260: 7 | I260: 59.3 | J260: 88.8 | K260: =IF(COUNTIFS($A$2:A260, A260, $C$2:C260, C260)>1, "Duplicate", "Unique") -> Unique | L260: =IF(G260 > (AVERAGE($G$2:$G$811) + (3 * _xlfn.STDEV.P($G$2:$G$811))), "Extreme Idle Outlier", "Normal") -> Normal | M260: =IFERROR(IF((D260 / E260) < 3, "Suspiciously Low Efficiency", "Normal"),0) -> Normal
A261: VH-007 | B261: Driver G | C261: 46041 | D261: 376 | E261: 78.4 | F261: =IFERROR(D261/E261,0) -> 4.7959184 | G261: 2.2 | H261: 1 | I261: 37.9 | J261: 92.5 | K261: =IF(COUNTIFS($A$2:A261, A261, $C$2:C261, C261)>1, "Duplicate", "Unique") -> Unique | L261: =IF(G261 > (AVERAGE($G$2:$G$811) + (3 * _xlfn.STDEV.P($G$2:$G$811))), "Extreme Idle Outlier", "Normal") -> Normal | M261: =IFERROR(IF((D261 / E261) < 3, "Suspiciously Low Efficiency", "Normal"),0) -> Normal
A262: VH-007 | B262: Driver G | C262: 46066 | D262: 235.5 | E262: 47.9 | F262: =IFERROR(D262/E262,0) -> 4.9164927 | G262: 2.3 | H262: 6 | I262: 50.9 | J262: 96.9 | K262: =IF(COUNTIFS($A$2:A262, A262, $C$2:C262, C262)>1, "Duplicate", "Unique") -> Unique | L262: =IF(G262 > (AVERAGE($G$2:$G$811) + (3 * _xlfn.STDEV.P($G$2:$G$811))), "Extreme Idle Outlier", "Normal") -> Normal | M262: =IFERROR(IF((D262 / E262) < 3, "Suspiciously Low Efficiency", "Normal"),0) -> Normal
A263: VH-007 | B263: Driver G | C263: 46055 | D263: 382.4 | E263: 75.9 | F263: =IFERROR(D263/E263,0) -> 5.0382082 | G263: 0.7 | H263: 4 | I263: 47.3 | J263: 99.6 | K263: =IF(COUNTIFS($A$2:A263, A263, $C$2:C263, C263)>1, "Duplicate", "Unique") -> Unique | L263: =IF(G263 > (AVERAGE($G$2:$G$811) + (3 * _xlfn.STDEV.P($G$2:$G$811))), "Extreme Idle Outlier", "Normal") -> Normal | M263: =IFERROR(IF((D263 / E263) < 3, "Suspiciously Low Efficiency", "Normal"),0) -> Normal
A264: VH-007 | B264: Driver G | C264: 46069 | D264: 408.4 | E264: 79.6 | F264: =IFERROR(D264/E264,0) -> 5.1306533 | G264: 1.1 | H264: 2 | I264: 40.6 | J264: 91.5 | K264: =IF(COUNTIFS($A$2:A264, A264, $C$2:C264, C264)>1, "Duplicate", "Unique") -> Unique | L264: =IF(G264 > (AVERAGE($G$2:$G$811) + (3 * _xlfn.STDEV.P($G$2:$G$811))), "Extreme Idle Outlier", "Normal") -> Normal | M264: =IFERROR(IF((D264 / E264) < 3, "Suspiciously Low Efficiency", "Normal"),0) -> Normal
A265: VH-007 | B265: Driver G | C265: 46071 | D265: 363.3 | E265: 68.5 | F265: =IFERROR(D265/E265,0) -> 5.3036496 | G265: 1.3 | H265: 8 | I265: 50.1 | J265: 91 | K265: =IF(COUNTIFS($A$2:A265, A265, $C$2:C265, C265)>1, "Duplicate", "Unique") -> Unique | L265: =IF(G265 > (AVERAGE($G$2:$G$811) + (3 * _xlfn.STDEV.P($G$2:$G$811))), "Extreme Idle Outlier", "Normal") -> Normal | M265: =IFERROR(IF((D265 / E265) < 3, "Suspiciously Low Efficiency", "Normal"),0) -> Normal
A266: VH-007 | B266: Driver G | C266: 46063 | D266: 88 | E266: 17.5 | F266: =IFERROR(D266/E266,0) -> 5.0285714 | G266: 3.2 | H266: 5 | I266: 71.4 | J266: 92.7 | K266: =IF(COUNTIFS($A$2:A266, A266, $C$2:C266, C266)>1, "Duplicate", "Unique") -> Unique | L266: =IF(G266 > (AVERAGE($G$2:$G$811) + (3 * _xlfn.STDEV.P($G$2:$G$811))), "Extreme Idle Outlier", "Normal") -> Normal | M266: =IFERROR(IF((D266 / E266) < 3, "Suspiciously Low Efficiency", "Normal"),0) -> Normal
A267: VH-007 | B267: Driver G | C267: 46112 | D267: 308.6 | E267: 104.8 | F267: =IFERROR(D267/E267,0) -> 2.9446565 | G267: 3 | H267: 1 | I267: 33 | J267: 94.9 | K267: =IF(COUNTIFS($A$2:A267, A267, $C$2:C267, C267)>1, "Duplicate", "Unique") -> Unique | L267: =IF(G267 > (AVERAGE($G$2:$G$811) + (3 * _xlfn.STDEV.P($G$2:$G$811))), "Extreme Idle Outlier", "Normal") -> Normal | M267: =IFERROR(IF((D267 / E267) < 3, "Suspiciously Low Efficiency", "Normal"),0) -> Suspiciously Low Efficiency
A268: VH-007 | B268: Driver G | C268: 46040 | D268: 194.3 | E268: 41.3 | F268: =IFERROR(D268/E268,0) -> 4.7046005 | G268: 2.5 | H268: 3 | I268: 49.4 | J268: 98.6 | K268: =IF(COUNTIFS($A$2:A268, A268, $C$2:C268, C268)>1, "Duplicate", "Unique") -> Duplicate | L268: =IF(G268 > (AVERAGE($G$2:$G$811) + (3 * _xlfn.STDEV.P($G$2:$G$811))), "Extreme Idle Outlier", "Normal") -> Normal | M268: =IFERROR(IF((D268 / E268) < 3, "Suspiciously Low Efficiency", "Normal"),0) -> Normal
A269: VH-007 | B269: Driver G | C269: 46112 | D269: 157.3 | E269: 53.2 | F269: =IFERROR(D269/E269,0) -> 2.9567669 | G269: 2.7 | H269: 2 | I269: 51.8 | J269: 95.3 | K269: =IF(COUNTIFS($A$2:A269, A269, $C$2:C269, C269)>1, "Duplicate", "Unique") -> Duplicate | L269: =IF(G269 > (AVERAGE($G$2:$G$811) + (3 * _xlfn.STDEV.P($G$2:$G$811))), "Extreme Idle Outlier", "Normal") -> Normal | M269: =IFERROR(IF((D269 / E269) < 3, "Suspiciously Low Efficiency", "Normal"),0) -> Suspiciously Low Efficiency
... A301: VH-008 | B301: Driver H | C301: 46051 | D301: 336.6 | E301: 90.2 | F301: =IFERROR(D301/E301,0) -> 3.7317073 | G301: 0.8 | H301: 7 | I301: 52.7 | J301: 89.6 | K301: =IF(COUNTIFS($A$2:A301, A301, $C$2:C301, C301)>1, "Duplicate", "Unique") -> Unique | L301: =IF(G301 > (AVERAGE($G$2:$G$811) + (3 * _xlfn.STDEV.P($G$2:$G$811))), "Extreme Idle Outlier", "Normal") -> Normal | M301: =IFERROR(IF((D301 / E301) < 3, "Suspiciously Low Efficiency", "Normal"),0) -> Normal
A302: VH-008 | B302: Driver H | C302: 46023 | D302: 84.7 | E302: 27.9 | F302: =IFERROR(D302/E302,0) -> 3.0358423 | H302: 8 | I302: 36.7 | J302: 86.4 | K302: =IF(COUNTIFS($A$2:A302, A302, $C$2:C302, C302)>1, "Duplicate", "Unique") -> Duplicate | L302: =IF(G302 > (AVERAGE($G$2:$G$811) + (3 * _xlfn.STDEV.P($G$2:$G$811))), "Extreme Idle Outlier", "Normal") -> Normal | M302: =IFERROR(IF((D302 / E302) < 3, "Suspiciously Low Efficiency", "Normal"),0) -> Normal
A303: VH-008 | B303: Driver H | C303: 46058 | D303: 227.2 | E303: 61 | F303: =IFERROR(D303/E303,0) -> 3.7245902 | G303: 1.5 | H303: 3 | I303: 36.2 | J303: 94 | K303: =IF(COUNTIFS($A$2:A303, A303, $C$2:C303, C303)>1, "Duplicate", "Unique") -> Duplicate | L303: =IF(G303 > (AVERAGE($G$2:$G$811) + (3 * _xlfn.STDEV.P($G$2:$G$811))), "Extreme Idle Outlier", "Normal") -> Normal | M303: =IFERROR(IF((D303 / E303) < 3, "Suspiciously Low Efficiency", "Normal"),0) -> Normal
A304: VH-008 | B304: Driver H | C304: 46046 | D304: 272.6 | E304: 55.4 | F304: =IFERROR(D304/E304,0) -> 4.9205776 | G304: 0.9 | H304: 7 | I304: 34.1 | J304: 88.3 | K304: =IF(COUNTIFS($A$2:A304, A304, $C$2:C304, C304)>1, "Duplicate", "Unique") -> Unique | L304: =IF(G304 > (AVERAGE($G$2:$G$811) + (3 * _xlfn.STDEV.P($G$2:$G$811))), "Extreme Idle Outlier", "Normal") -> Normal | M304: =IFERROR(IF((D304 / E304) < 3, "Suspiciously Low Efficiency", "Normal"),0) -> Normal
A305: VH-008 | B305: Driver H | C305: 46089 | D305: 230.2 | E305: 46 | F305: =IFERROR(D305/E305,0) -> 5.0043478 | G305: 1.7 | H305: 8 | I305: 69.9 | J305: 85.1 | K305: =IF(COUNTIFS($A$2:A305, A305, $C$2:C305, C305)>1, "Duplicate", "Unique") -> Unique | L305: =IF(G305 > (AVERAGE($G$2:$G$811) + (3 * _xlfn.STDEV.P($G$2:$G$811))), "Extreme Idle Outlier", "Normal") -> Normal | M305: =IFERROR(IF((D305 / E305) < 3, "Suspiciously Low Efficiency", "Normal"),0) -> Normal
A306: VH-008 | B306: Driver H | C306: 46100 | D306: 436.3 | E306: 108.3 | F306: =IFERROR(D306/E306,0) -> 4.0286242 | G306: 1.9 | H306: 1 | I306: 41.7 | J306: 91.1 | K306: =IF(COUNTIFS($A$2:A306, A306, $C$2:C306, C306)>1, "Duplicate", "Unique") -> Unique | L306: =IF(G306 > (AVERAGE($G$2:$G$811) + (3 * _xlfn.STDEV.P($G$2:$G$811))), "Extreme Idle Outlier", "Normal") -> Normal | M306: =IFERROR(IF((D306 / E306) < 3, "Suspiciously Low Efficiency", "Normal"),0) -> Normal
A307: VH-008 | B307: Driver H | C307: 46109 | D307: 339.4 | E307: 68.4 | F307: =IFERROR(D307/E307,0) -> 4.9619883 | G307: 2 | H307: 6 | I307: 53.2 | J307: 85.1 | K307: =IF(COUNTIFS($A$2:A307, A307, $C$2:C307, C307)>1, "Duplicate", "Unique") -> Duplicate | L307: =IF(G307 > (AVERAGE($G$2:$G$811) + (3 * _xlfn.STDEV.P($G$2:$G$811))), "Extreme Idle Outlier", "Normal") -> Normal | M307: =IFERROR(IF((D307 / E307) < 3, "Suspiciously Low Efficiency", "Normal"),0) -> Normal
A308: VH-008 | B308: Driver H | C308: 46056 | D308: 156.5 | E308: 46.8 | F308: =IFERROR(D308/E308,0) -> 3.3440171 | G308: 1.3 | H308: 6 | I308: 37 | J308: 86.6 | K308: =IF(COUNTIFS($A$2:A308, A308, $C$2:C308, C308)>1, "Duplicate", "Unique") -> Unique | L308: =IF(G308 > (AVERAGE($G$2:$G$811) + (3 * _xlfn.STDEV.P($G$2:$G$811))), "Extreme Idle Outlier", "Normal") -> Normal | M308: =IFERROR(IF((D308 / E308) < 3, "Suspiciously Low Efficiency", "Normal"),0) -> Normal
A309: VH-008 | B309: Driver H | C309: 46089 | D309: 362.9 | E309: 69 | F309: =IFERROR(D309/E309,0) -> 5.2594203 | G309: 3.7 | H309: 5 | I309: 42.8 | J309: 96.1 | K309: =IF(COUNTIFS($A$2:A309, A309, $C$2:C309, C309)>1, "Duplicate", "Unique") -> Duplicate | L309: =IF(G309 > (AVERAGE($G$2:$G$811) + (3 * _xlfn.STDEV.P($G$2:$G$811))), "Extreme Idle Outlier", "Normal") -> Normal | M309: =IFERROR(IF((D309 / E309) < 3, "Suspiciously Low Efficiency", "Normal"),0) -> Normal
A310: VH-008 | B310: Driver H | C310: 46027 | D310: 153.7 | E310: 32.1 | F310: =IFERROR(D310/E310,0) -> 4.788162 | G310: 0.6 | H310: 4 | I310: 51.3 | J310: 95.2 | K310: =IF(COUNTIFS($A$2:A310, A310, $C$2:C310, C310)>1, "Duplicate", "Unique") -> Unique | L310: =IF(G310 > (AVERAGE($G$2:$G$811) + (3 * _xlfn.STDEV.P($G$2:$G$811))), "Extreme Idle Outlier", "Normal") -> Normal | M310: =IFERROR(IF((D310 / E310) < 3, "Suspiciously Low Efficiency", "Normal"),0) -> Normal
A311: VH-008 | B311: Driver H | C311: 46052 | D311: 174.8 | E311: 48.4 | F311: =IFERROR(D311/E311,0) -> 3.6115702 | G311: 2.7 | H311: 4 | I311: 63 | J311: 95.9 | K311: =IF(COUNTIFS($A$2:A311, A311, $C$2:C311, C311)>1, "Duplicate", "Unique") -> Unique | L311: =IF(G311 > (AVERAGE($G$2:$G$811) + (3 * _xlfn.STDEV.P($G$2:$G$811))), "Extreme Idle Outlier", "Normal") -> Normal | M311: =IFERROR(IF((D311 / E311) < 3, "Suspiciously Low Efficiency", "Normal"),0) -> Normal
A312: VH-008 | B312: Driver H | C312: 46048 | D312: 333.6 | E312: 103.6 | F312: =IFERROR(D312/E312,0) -> 3.2200772 | G312: 3.3 | H312: 2 | I312: 35.1 | J312: 85.8 | K312: =IF(COUNTIFS($A$2:A312, A312, $C$2:C312, C312)>1, "Duplicate", "Unique") -> Unique | L312: =IF(G312 > (AVERAGE($G$2:$G$811) + (3 * _xlfn.STDEV.P($G$2:$G$811))), "Extreme Idle Outlier", "Normal") -> Normal | M312: =IFERROR(IF((D312 / E312) < 3, "Suspiciously Low Efficiency", "Normal"),0) -> Normal
A313: VH-008 | B313: Driver H | C313: 46045 | D313: 325.2 | E313: 108 | F313: =IFERROR(D313/E313,0) -> 3.0111111 | G313: 4.2 | H313: 8 | I313: 35.1 | J313: 93.9 | K313: =IF(COUNTIFS($A$2:A313, A313, $C$2:C313, C313)>1, "Duplicate", "Unique") -> Unique | L313: =IF(G313 > (AVERAGE($G$2:$G$811) + (3 * _xlfn.STDEV.P($G$2:$G$811))), "Extreme Idle Outlier", "Normal") -> Normal | M313: =IFERROR(IF((D313 / E313) < 3, "Suspiciously Low Efficiency", "Normal"),0) -> Normal
...

Sheet Fuel_Events
A1: Vehicle_ID | B1: Timestamp | C1: Event_Type | D1: Quantity_L | E1: Location
A2: VH-002 | B2: 46057.117 | C2: Consumption Alert | D2: 19.7 | E2: Vadodara
A3: VH-013 | B3: 46091.723 | C3: Refuel | D3: 130.8 | E3: Ahmedabad
A4: VH-005 | B4: 46066.723 | C4: Fuel Drop | D4: 14 | E4: Rajkot
A5: VH-003 | B5: 46099.503 | C5: Fuel Fill | D5: 61 | E5: Rajkot
A6: VH-004 | B6: 46028.113 | C6: Fuel Drop | D6: 11.9 | E6: Vadodara
A7: VH-010 | B7: 46078.771 | C7: Refuel | D7: 81 | E7: Vadodara
A8: VH-010 | B8: 46066.702 | C8: Consumption Alert | D8: 16.4 | E8: Bharuch
A9: VH-017 | B9: 46095.417 | C9: Consumption Alert | D9: 54.1 | E9: Indore
A10: VH-017 | B10: 46078.899 | C10: Consumption Alert | D10: 33.6 | E10: Rajkot
A11: VH-012 | B11: 46088.079 | C11: Fuel Drop | D11: 44.9 | E11: Vadodara
A12: VH-016 | B12: 46107.34 | C12: Refuel | D12: 63.8 | E12: Rajkot
A13: VH-003 | B13: 46081.525 | C13: Refuel | D13: 22.1 | E13: Bharuch
... A304: VH-007 | B304: 46086.132 | C304: Fuel Drop | D304: 44.3 | E304: Remote Route

Sheet Task 4 Fuel Investigation
A1: Vehicle_ID | B1: Timestamp | C1: Hour | D1: Event_Type | E1: Quantity_L | F1: Location | H1: Que 1 | I1: Identify suspicious fuel drop patterns | P1: Que 3 | Q1: Identify vehicles with repeated fuel-drop incidents.
A2: VH-001 | B2: 46067.622 | C2: =HOUR(B2) -> 14 | D2: Consumption Alert | E2: 21.7 | F2: Vadodara
A3: VH-001 | B3: 46055.953 | C3: =HOUR(B3) -> 22 | D3: Consumption Alert | E3: 23.7 | F3: Ahmedabad | H3: Row Labels | I3: Count of Quantity_L | J3: Average of Quantity_L | K3: Max of Quantity_L
A4: VH-001 | B4: 46086.882 | C4: =HOUR(B4) -> 21 | D4: Fuel Drop | E4: 7.6 | F4: Bharuch | H4: Consumption Alert | I4: 73 | J4: 31.49863 | K4: 60 | P4: Event_Type | Q4: Fuel Drop
A5: VH-001 | B5: 46075.847 | C5: =HOUR(B5) -> 20 | D5: Fuel Fill | E5: 25.4 | F5: Ahmedabad | H5: Fuel Drop | I5: 96 | J5: 32.777083 | K5: 59.6
A6: VH-001 | B6: 46043.098 | C6: =HOUR(B6) -> 2 | D6: Fuel Fill | E6: 32.8 | F6: Ahmedabad | H6: Fuel Fill | I6: 71 | J6: 77.446479 | K6: 141.7 | P6: Row Labels | Q6: Fuel Drop Incidents | R6: Answer:
A7: VH-001 | B7: 46103.882 | C7: =HOUR(B7) -> 21 | D7: Fuel Drop | E7: 25.1 | F7: Vadodara | H7: Refuel | I7: 63 | J7: 80.860317 | K7: 149.7 | P7: VH-006 | Q7: 9 | R7: VH-005, VH-006, and VH-012 are the top repeat offenders with 9 fuel-drop incidents each, followed closely by VH-007 (8 incidents) and VH-001 (7 incidents). This repeated pattern indicates severe physical tank leaks or chronic fuel theft on these specific vehicles.
A8: VH-001 | B8: 46034.152 | C8: =HOUR(B8) -> 3 | D8: Fuel Fill | E8: 141.2 | F8: Rajkot | H8: Grand Total | I8: 303 | J8: 52.933663 | K8: 149.7 | P8: VH-005 | Q8: 9
A9: VH-001 | B9: 46052.635 | C9: =HOUR(B9) -> 15 | D9: Fuel Drop | E9: 13.5 | F9: Bharuch | P9: VH-012 | Q9: 9
A10: VH-001 | B10: 46093.172 | C10: =HOUR(B10) -> 4 | D10: Fuel Drop | E10: 14.8 | F10: Bharuch | P10: VH-007 | Q10: 8
A11: VH-001 | B11: 46106.107 | C11: =HOUR(B11) -> 2 | D11: Fuel Fill | E11: 66.5 | F11: Vadodara | H11: Que 2 | I11: Find fuel drops during unusual hours. | P11: VH-001 | Q11: 7
A12: VH-001 | B12: 46077.377 | C12: =HOUR(B12) -> 9 | D12: Fuel Drop | E12: 41.8 | F12: Surat | P12: VH-020 | Q12: 6
A13: VH-001 | B13: 46068.094 | C13: =HOUR(B13) -> 2 | D13: Fuel Drop | E13: 48.5 | F13: Remote Route | P13: VH-018 | Q13: 6
A14: VH-001 | B14: 46073.069 | C14: =HOUR(B14) -> 1 | D14: Fuel Drop | E14: 52.1 | F14: Remote Route | H14: Event_Type | I14: Fuel Drop | P14: VH-014 | Q14: 6
A15: VH-002 | B15: 46057.117 | C15: =HOUR(B15) -> 2 | D15: Consumption Alert | E15: 19.7 | F15: Vadodara | P15: VH-019 | Q15: 5
A16: VH-002 | B16: 46089.524 | C16: =HOUR(B16) -> 12 | D16: Refuel | E16: 39 | F16: Indore | H16: Row Labels | I16: Count of Quantity_L | P16: VH-004 | Q16: 4
A17: VH-002 | B17: 46077.122 | C17: =HOUR(B17) -> 2 | D17: Fuel Drop | E17: 14.4 | F17: Vadodara | H17: 0 | I17: 3 | P17: VH-003 | Q17: 4
A18: VH-002 | B18: 46111.698 | C18: =HOUR(B18) -> 16 | D18: Fuel Drop | E18: 25.3 | F18: Vadodara | H18: 1 | I18: 6 | P18: VH-017 | Q18: 4
A19: VH-002 | B19: 46049.389 | C19: =HOUR(B19) -> 9 | D19: Refuel | E19: 39.7 | F19: Bharuch | H19: 2 | I19: 5 | P19: VH-011 | Q19: 4
A20: VH-002 | B20: 46105.809 | C20: =HOUR(B20) -> 19 | D20: Refuel | E20: 105.2 | F20: Ahmedabad | H20: 3 | I20: 4 | P20: VH-002 | Q20: 3
A21: VH-002 | B21: 46108.476 | C21: =HOUR(B21) -> 11 | D21: Consumption Alert | E21: 40.4 | F21: Ahmedabad | H21: 4 | I21: 5 | P21: VH-013 | Q21: 3
A22: VH-002 | B22: 46074.09 | C22: =HOUR(B22) -> 2 | D22: Fuel Fill | E22: 37.2 | F22: Indore | H22: 5 | I22: 3 | P22: VH-008 | Q22: 3
A23: VH-002 | B23: 46036.165 | C23: =HOUR(B23) -> 3 | D23: Consumption Alert | E23: 26.5 | F23: Bharuch | H23: 6 | I23: 4 | P23: VH-015 | Q23: 2
A24: VH-002 | B24: 46056.304 | C24: =HOUR(B24) -> 7 | D24: Consumption Alert | E24: 41.9 | F24: Ahmedabad | H24: 7 | I24: 5 | P24: VH-010 | Q24: 2
A25: VH-002 | B25: 46048.631 | C25: =HOUR(B25) -> 15 | D25: Refuel | E25: 110.2 | F25: Surat | H25: 8 | I25: 4 | P25: VH-009 | Q25: 1
A26: VH-002 | B26: 46105.917 | C26: =HOUR(B26) -> 22 | D26: Fuel Drop | E26: 47.8 | F26: Ahmedabad | H26: 9 | I26: 5 | P26: VH-016 | Q26: 1
A27: VH-003 | B27: 46099.503 | C27: =HOUR(B27) -> 12 | D27: Fuel Fill | E27: 61 | F27: Rajkot | H27: 10 | I27: 7 | P27: Grand Total | Q27: 96
A28: VH-003 | B28: 46081.525 | C28: =HOUR(B28) -> 12 | D28: Refuel | E28: 22.1 | F28: Bharuch | H28: 11 | I28: 4
A29: VH-003 | B29: 46103.458 | C29: =HOUR(B29) -> 11 | D29: Refuel | E29: 149.7 | F29: Rajkot | H29: 12 | I29: 1
A30: VH-003 | B30: 46109.183 | C30: =HOUR(B30) -> 4 | D30: Fuel Drop | E30: 45.9 | F30: Indore | H30: 13 | I30: 2
A31: VH-003 | B31: 46048.675 | C31: =HOUR(B31) -> 16 | D31: Fuel Fill | E31: 45.2 | F31: Bharuch | H31: 14 | I31: 3
A32: VH-003 | B32: 46109.012 | C32: =HOUR(B32) -> 0 | D32: Refuel | E32: 107 | F32: Surat | H32: 15 | I32: 3
A33: VH-003 | B33: 46064.603 | C33: =HOUR(B33) -> 14 | D33: Fuel Fill | E33: 34.5 | F33: Indore | H33: 16 | I33: 6
A34: VH-003 | B34: 46111.141 | C34: =HOUR(B34) -> 3 | D34: Fuel Drop | E34: 15.5 | F34: Vadodara | H34: 17 | I34: 4
A35: VH-003 | B35: 46057.358 | C35: =HOUR(B35) -> 8 | D35: Refuel | E35: 54.6 | F35: Ahmedabad | H35: 18 | I35: 1
A36: VH-003 | B36: 46069.226 | C36: =HOUR(B36) -> 5 | D36: Refuel | E36: 142.3 | F36: Rajkot | H36: 19 | I36: 2
A37: VH-003 | B37: 46088.731 | C37: =HOUR(B37) -> 17 | D37: Consumption Alert | E37: 34.6 | F37: Rajkot | H37: 20 | I37: 4
A38: VH-003 | B38: 46087.271 | C38: =HOUR(B38) -> 6 | D38: Refuel | E38: 91.8 | F38: Indore | H38: 21 | I38: 6
A39: VH-003 | B39: 46041.609 | C39: =HOUR(B39) -> 14 | D39: Fuel Drop | E39: 50.2 | F39: Ahmedabad | H39: 22 | I39: 5
A40: VH-003 | B40: 46069.29 | C40: =HOUR(B40) -> 6 | D40: Fuel Fill | E40: 111.4 | F40: Vadodara | H40: 23 | I40: 4
...

Sheet Task 4 Fuel Investigation Q-4&5
A1: Event_Type | B1: Fuel Drop | H1: Vehicle ID | I1: Fuel Drop Count | J1: Route Compliance % | K1: Diagnosis (Theft vs. Leakage) | N1: Que 5 | O1: Recommended actions to reduce fuel losses
H2: VH-012 | I2: 9 | J2: 89.984211 | K2: High-Risk Theft Suspect
A3: Row Labels | B3: Count of Quantity_L | E3: Row Labels | F3: Average of Route_Compliance_Pct | H3: VH-006 | I3: 9 | J3: 92.487273 | K3: Potential Mechanical Leakage | N3: Ans: | O3: To systematically mitigate the identified fuel losses, the fleet should execute a dual-track strategy targeting both security and maintenance
A4: VH-012 | B4: 9 | E4: VH-012 | F4: 89.984211 | H4: VH-005 | I4: 9 | J4: 93.710204 | K4: Potential Mechanical Leakage | N4: - | O4: For Theft (Below 92.53%): Set up real-time geofencing alerts and install smart-locking fuel caps on VH-012 and VH-001 to block off-route siphoning.
A5: VH-006 | B5: 9 | E5: VH-001 | F5: 91.186486 | H5: VH-007 | I5: 8 | J5: 92.6875 | K5: Potential Mechanical Leakage | N5: - | O5: For Leakage (Above 92.53%): Send VH-005 and VH-007 for immediate physical tank pressure tests to fix hardware leaks.
A6: VH-005 | B6: 9 | E6: VH-004 | F6: 91.519512 | H6: VH-001 | I6: 7 | J6: 91.186486 | K6: High-Risk Theft Suspect | N6: - | O6: Night Security: Turn on instant security alerts for any fuel drops logged during the high-risk night window (10:00 PM – 5:00 AM).
A7: VH-007 | B7: 8 | E7: VH-019 | F7: 91.871429 | H7: VH-014 | I7: 6 | J7: 92.579412 | K7: High-Risk Theft Suspect
A8: VH-001 | B8: 7 | E8: VH-003 | F8: 92.108333 | H8: VH-018 | I8: 6 | J8: 92.487273 | K8: Potential Mechanical Leakage
A9: VH-014 | B9: 6 | E9: VH-017 | F9: 92.182857 | H9: VH-020 | I9: 6 | J9: 93.38125 | K9: Potential Mechanical Leakage
A10: VH-018 | B10: 6 | E10: VH-002 | F10: 92.437143 | H10: VH-019 | I10: 5 | J10: 91.871429 | K10: High-Risk Theft Suspect
A11: VH-020 | B11: 6 | E11: VH-018 | F11: 92.487273 | H11: VH-003 | I11: 4 | J11: 92.108333 | K11: High-Risk Theft Suspect
A12: VH-019 | B12: 5 | E12: VH-006 | F12: 92.5 | H12: VH-017 | I12: 4 | J12: 92.182857 | K12: High-Risk Theft Suspect
A13: VH-003 | B13: 4 | E13: VH-008 | F13: 92.564286 | H13: VH-004 | I13: 4 | J13: 91.519512 | K13: High-Risk Theft Suspect
A14: VH-017 | B14: 4 | E14: VH-014 | F14: 92.579412 | H14: VH-011 | I14: 4 | J14: 93.328846 | K14: Potential Mechanical Leakage
A15: VH-004 | B15: 4 | E15: VH-007 | F15: 92.6875 | H15: VH-008 | I15: 3 | J15: 92.564286 | K15: Potential Mechanical Leakage
A16: VH-011 | B16: 4 | E16: VH-016 | F16: 92.878049 | H16: VH-013 | I16: 3 | J16: 92.897143 | K16: High-Risk Theft Suspect
A17: VH-008 | B17: 3 | E17: VH-013 | F17: 92.897143 | H17: VH-002 | I17: 3 | J17: 92.437143 | K17: High-Risk Theft Suspect
A18: VH-013 | B18: 3 | E18: VH-015 | F18: 93.039394 | H18: VH-015 | I18: 2 | J18: 93.039394 | K18: Potential Mechanical Leakage
... A21: VH-010 | B21: 2 | E21: VH-011 | F21: 93.328846 | H21: VH-009 | I21: 1 | J21: 93.15 | K21: Potential Mechanical Leakage
A22: VH-016 | B22: 1 | E22: VH-020 | F22: 93.38125
A23: VH-009 | B23: 1 | E23: VH-005 | F23: 93.710204 | G23: Reasoning | H23: Why the Baseline is 92.53%
A24: Grand Total | B24: 96 | E24: Grand Total | F24: 92.529193 | G24: Ans | H24: We use 92.53% because it is the average route compliance for the entire fleet. It acts as our dividing line
G25: - | H25: Below 92.53% = Theft Suspects: These vehicles are leaving their assigned routes and losing fuel, which points to off-route fuel siphoning.
G26: - | H26: Above 92.53% = Leakage Suspects: These vehicles are following their routes perfectly but are still losing fuel, pointing to a physical tank leak or mechanical issue.
G28: → | H28: Fuel Theft Case (VH-012): Suffers 9 severe fuel drops combined with the fleet's worst route compliance 89.98%, proving off-route siphoning.
G29: → | H29: Mechanical Leakage Case (VH-005): Suffers the same extreme drop frequency (9 incidents) but maintains highly stable, compliant routing, indicating a physical tank leak.
